Workbook

Sheet Hoja1
B1: top-left-square | C1: top-middle-square | D1: top-right-square | E1: middle-left-square | F1: middle-middle-square | G1: middle-right-square | H1: bottom-left-square | I1: bottom-middle-square | J1: bottom-right-square
A2: Entropía general | B2: =ROUND(C17*LOG(C17,2)+C18*LOG(C18,2),3)*-1 -> 0.912 | C2: =B2 -> 0.912 | D2: =C2 -> 0.912 | E2: =D2 -> 0.912 | F2: =E2 -> 0.912 | G2: =F2 -> 0.912 | H2: =G2 -> 0.912 | I2: =H2 -> 0.912 | J2: =I2 -> 0.912
A3: Entropía X | B3: =ROUND((((B9/(B9+B10))*LOG(B9/(B9+B10),2))+((B10/(B9+B10))*LOG(B10/(B9+B10),2)))*-1,3) -> 0.752 | C3: =ROUND((((C9/(C9+C10))*LOG(C9/(C9+C10),2))+((C10/(C9+C10))*LOG(C10/(C9+C10),2)))*-1,3) -> 0.923 | D3: =ROUND((((D9/(D9+D10))*LOG(D9/(D9+D10),2))+((D10/(D9+D10))*LOG(D10/(D9+D10),2)))*-1,3) -> 0.839 | E3: =ROUND((((E9/(E9+E10))*LOG(E9/(E9+E10),2))+((E10/(E9+E10))*LOG(E10/(E9+E10),2)))*-1,3) -> 0.963 | F3: =ROUND((((F9/(F9+F10))*LOG(F9/(F9+F10),2))+((F10/(F9+F10))*LOG(F10/(F9+F10),2)))*-1,3) -> 0.711 | G3: =ROUND((((G9/(G9+G10))*LOG(G9/(G9+G10),2))+((G10/(G9+G10))*LOG(G10/(G9+G10),2)))*-1,3) -> 0.973 | H3: =ROUND((((H9/(H9+H10))*LOG(H9/(H9+H10),2))+((H10/(H9+H10))*LOG(H10/(H9+H10),2)))*-1,3) -> 0.87 | I3: =ROUND((((I9/(I9+I10))*LOG(I9/(I9+I10),2))+((I10/(I9+I10))*LOG(I10/(I9+I10),2)))*-1,3) -> 0.973 | J3: =ROUND((((J9/(J9+J10))*LOG(J9/(J9+J10),2))+((J10/(J9+J10))*LOG(J10/(J9+J10),2)))*-1,3) -> 0.867
A4: Entropía B | B4: =ROUND((((B11/(B12+B11))*LOG(B11/(B12+B11),2))+((B12/(B11+B12))*LOG(B12/(B11+B12),2)))*-1,3) -> 0.959 | C4: =ROUND((((C11/(C12+C11))*LOG(C11/(C12+C11),2))+((C12/(C11+C12))*LOG(C12/(C11+C12),2)))*-1,3) -> 0.947 | D4: =ROUND((((D11/(D12+D11))*LOG(D11/(D12+D11),2))+((D12/(D11+D12))*LOG(D12/(D11+D12),2)))*-1,3) -> 0.906 | E4: =ROUND((((E11/(E12+E11))*LOG(E11/(E12+E11),2))+((E12/(E11+E12))*LOG(E12/(E11+E12),2)))*-1,3) -> 0.86 | F4: =ROUND((((F11/(F12+F11))*LOG(F11/(F12+F11),2))+((F12/(F11+F12))*LOG(F12/(F11+F12),2)))*-1,3) -> 0.848 | G4: =ROUND((((G11/(G12+G11))*LOG(G11/(G12+G11),2))+((G12/(G11+G12))*LOG(G12/(G11+G12),2)))*-1,3) -> 0.871 | H4: =ROUND((((H11/(H12+H11))*LOG(H11/(H12+H11),2))+((H12/(H11+H12))*LOG(H12/(H11+H12),2)))*-1,3) -> 0.863 | I4: =ROUND((((I11/(I12+I11))*LOG(I11/(I12+I11),2))+((I12/(I11+I12))*LOG(I12/(I11+I12),2)))*-1,3) -> 0.858 | J4: =ROUND((((J11/(J12+J11))*LOG(J11/(J12+J11),2))+((J12/(J11+J12))*LOG(J12/(J11+J12),2)))*-1,3) -> 0.857
A5: Entropía O | B5: =ROUND((((B13/(B14+B13))*LOG(B13/(B14+B13),2))+((B14/(B13+B14))*LOG(B14/(B13+B14),2)))*-1,3) -> 0.987 | C5: =ROUND((((C13/(C14+C13))*LOG(C13/(C14+C13),2))+((C14/(C13+C14))*LOG(C14/(C13+C14),2)))*-1,3) -> 0.867 | D5: =ROUND((((D13/(D14+D13))*LOG(D13/(D14+D13),2))+((D14/(D13+D14))*LOG(D14/(D13+D14),2)))*-1,3) -> 0.975 | E5: =ROUND((((E13/(E14+E13))*LOG(E13/(E14+E13),2))+((E14/(E13+E14))*LOG(E14/(E13+E14),2)))*-1,3) -> 0.866 | F5: =ROUND((((F13/(F14+F13))*LOG(F13/(F14+F13),2))+((F14/(F13+F14))*LOG(F14/(F13+F14),2)))*-1,3) -> 0.995 | G5: =ROUND((((G13/(G14+G13))*LOG(G13/(G14+G13),2))+((G14/(G13+G14))*LOG(G14/(G13+G14),2)))*-1,3) -> 0.836 | H5: =ROUND((((H13/(H14+H13))*LOG(H13/(H14+H13),2))+((H14/(H13+H14))*LOG(H14/(H13+H14),2)))*-1,3) -> 0.971 | I5: =ROUND((((I13/(I14+I13))*LOG(I13/(I14+I13),2))+((I14/(I13+I14))*LOG(I14/(I13+I14),2)))*-1,3) -> 0.847 | J5: =ROUND((((J13/(J14+J13))*LOG(J13/(J14+J13),2))+((J14/(J13+J14))*LOG(J14/(J13+J14),2)))*-1,3) -> 0.973
A6: Entropía final | B6: =ROUND(((((B9+B10)/B15)*B3)+(((B11+B12)/B15)*B4)+(((B13+B14)/B15)*B5)),3) -> 0.877 | C6: =ROUND(((((C9+C10)/C15)*C3)+(((C11+C12)/C15)*C4)+(((C13+C14)/C15)*C5)),3) -> 0.908 | D6: =ROUND(((((D9+D10)/D15)*D3)+(((D11+D12)/D15)*D4)+(((D13+D14)/D15)*D5)),3) -> 0.9 | E6: =ROUND(((((E9+E10)/E15)*E3)+(((E11+E12)/E15)*E4)+(((E13+E14)/E15)*E5)),3) -> 0.903 | F6: =ROUND(((((F9+F10)/F15)*F3)+(((F11+F12)/F15)*F4)+(((F13+F14)/F15)*F5)),3) -> 0.831 | G6: =ROUND(((((G9+G10)/G15)*G3)+(((G11+G12)/G15)*G4)+(((G13+G14)/G15)*G5)),3) -> 0.898 | H6: =ROUND(((((H9+H10)/H15)*H3)+(((H11+H12)/H15)*H4)+(((H13+H14)/H15)*H5)),3) -> 0.903 | I6: =ROUND(((((I9+I10)/I15)*I3)+(((I11+I12)/I15)*I4)+(((I13+I14)/I15)*I5)),3) -> 0.899 | J6: =ROUND(((((J9+J10)/J15)*J3)+(((J11+J12)/J15)*J4)+(((J13+J14)/J15)*J5)),3) -> 0.901
A7: Ganancia | B7: =ROUND((B2-B6),3) -> 0.035 | C7: =ROUND((C2-C6),3) -> 0.004 | D7: =ROUND((D2-D6),3) -> 0.012 | E7: =ROUND((E2-E6),3) -> 0.009 | F7: =ROUND((F2-F6),3) -> 0.081 | G7: =ROUND((G2-G6),3) -> 0.014 | H7: =ROUND((H2-H6),3) -> 0.009 | I7: =ROUND((I2-I6),3) -> 0.013 | J7: =ROUND((J2-J6),3) -> 0.011
A9: X positivos | B9: =COUNTIFS(TRAIN!A:A,"x",TRAIN!J:J,"positive") -> 295 | C9: =COUNTIFS(TRAIN!B:B,"x",TRAIN!J:J,"positive") -> 215 | D9: =COUNTIFS(TRAIN!C:C,"x",TRAIN!J:J,"positive") -> 273 | E9: =COUNTIFS(TRAIN!D:D,"x",TRAIN!J:J,"positive") -> 209 | F9: =COUNTIFS(TRAIN!E:E,"x",TRAIN!J:J,"positive") -> 335 | G9: =COUNTIFS(TRAIN!F:F,"x",TRAIN!J:J,"positive") -> 196 | H9: =COUNTIFS(TRAIN!G:G,"x",TRAIN!J:J,"positive") -> 268 | I9: =COUNTIFS(TRAIN!H:H,"x",TRAIN!J:J,"positive") -> 198 | J9: =COUNTIFS(TRAIN!I:I,"x",TRAIN!J:J,"positive") -> 264
A10: X negativos | B10: =COUNTIFS(TRAIN!A:A,"x",TRAIN!J:J,"negative") -> 81 | C10: =COUNTIFS(TRAIN!B:B,"x",TRAIN!J:J,"negative") -> 110 | D10: =COUNTIFS(TRAIN!C:C,"x",TRAIN!J:J,"negative") -> 100 | E10: =COUNTIFS(TRAIN!D:D,"x",TRAIN!J:J,"negative") -> 132 | F10: =COUNTIFS(TRAIN!E:E,"x",TRAIN!J:J,"negative") -> 81 | G10: =COUNTIFS(TRAIN!F:F,"x",TRAIN!J:J,"negative") -> 133 | H10: =COUNTIFS(TRAIN!G:G,"x",TRAIN!J:J,"negative") -> 110 | I10: =COUNTIFS(TRAIN!H:H,"x",TRAIN!J:J,"negative") -> 134 | J10: =COUNTIFS(TRAIN!I:I,"x",TRAIN!J:J,"negative") -> 107
A11: B positivos | B11: =COUNTIFS(TRAIN!A:A,"b",TRAIN!J:J,"positive") -> 102 | C11: =COUNTIFS(TRAIN!B:B,"b",TRAIN!J:J,"positive") -> 132 | D11: =COUNTIFS(TRAIN!C:C,"b",TRAIN!J:J,"positive") -> 129 | E11: =COUNTIFS(TRAIN!D:D,"b",TRAIN!J:J,"positive") -> 157 | F11: =COUNTIFS(TRAIN!E:E,"b",TRAIN!J:J,"positive") -> 103 | G11: =COUNTIFS(TRAIN!F:F,"b",TRAIN!J:J,"positive") -> 160 | H11: =COUNTIFS(TRAIN!G:G,"b",TRAIN!J:J,"positive") -> 130 | I11: =COUNTIFS(TRAIN!H:H,"b",TRAIN!J:J,"positive") -> 158 | J11: =COUNTIFS(TRAIN!I:I,"b",TRAIN!J:J,"positive") -> 133
A12: B negativos | B12: =COUNTIFS(TRAIN!A:A,"b",TRAIN!J:J,"negative") -> 63 | C12: =COUNTIFS(TRAIN!B:B,"b",TRAIN!J:J,"negative") -> 76 | D12: =COUNTIFS(TRAIN!C:C,"b",TRAIN!J:J,"negative") -> 61 | E12: =COUNTIFS(TRAIN!D:D,"b",TRAIN!J:J,"negative") -> 62 | F12: =COUNTIFS(TRAIN!E:E,"b",TRAIN!J:J,"negative") -> 39 | G12: =COUNTIFS(TRAIN!F:F,"b",TRAIN!J:J,"negative") -> 66 | H12: =COUNTIFS(TRAIN!G:G,"b",TRAIN!J:J,"negative") -> 52 | I12: =COUNTIFS(TRAIN!H:H,"b",TRAIN!J:J,"negative") -> 62 | J12: =COUNTIFS(TRAIN!I:I,"b",TRAIN!J:J,"negative") -> 52
A13: O positivos | B13: =COUNTIFS(TRAIN!A:A,"o",TRAIN!J:J,"positive") -> 174 | C13: =COUNTIFS(TRAIN!B:B,"o",TRAIN!J:J,"positive") -> 224 | D13: =COUNTIFS(TRAIN!C:C,"o",TRAIN!J:J,"positive") -> 169 | E13: =COUNTIFS(TRAIN!D:D,"o",TRAIN!J:J,"positive") -> 205 | F13: =COUNTIFS(TRAIN!E:E,"o",TRAIN!J:J,"positive") -> 133 | G13: =COUNTIFS(TRAIN!F:F,"o",TRAIN!J:J,"positive") -> 215 | H13: =COUNTIFS(TRAIN!G:G,"o",TRAIN!J:J,"positive") -> 173 | I13: =COUNTIFS(TRAIN!H:H,"o",TRAIN!J:J,"positive") -> 215 | J13: =COUNTIFS(TRAIN!I:I,"o",TRAIN!J:J,"positive") -> 174
A14: O negativos | B14: =COUNTIFS(TRAIN!A:A,"o",TRAIN!J:J,"negative") -> 133 | C14: =COUNTIFS(TRAIN!B:B,"o",TRAIN!J:J,"negative") -> 91 | D14: =COUNTIFS(TRAIN!C:C,"o",TRAIN!J:J,"negative") -> 116 | E14: =COUNTIFS(TRAIN!D:D,"o",TRAIN!J:J,"negative") -> 83 | F14: =COUNTIFS(TRAIN!E:E,"o",TRAIN!J:J,"negative") -> 157 | G14: =COUNTIFS(TRAIN!F:F,"o",TRAIN!J:J,"negative") -> 78 | H14: =COUNTIFS(TRAIN!G:G,"o",TRAIN!J:J,"negative") -> 115 | I14: =COUNTIFS(TRAIN!H:H,"o",TRAIN!J:J,"negative") -> 81 | J14: =COUNTIFS(TRAIN!I:I,"o",TRAIN!J:J,"negative") -> 118
A15: Total | B15: =B9+B10+B11+B12+B13+B14 -> 848 | C15: =C9+C10+C11+C12+C13+C14 -> 848 | D15: =D9+D10+D11+D12+D13+D14 -> 848 | E15: =E9+E10+E11+E12+E13+E14 -> 848 | F15: =F9+F10+F11+F12+F13+F14 -> 848 | G15: =G9+G10+G11+G12+G13+G14 -> 848 | H15: =H9+H10+H11+H12+H13+H14 -> 848 | I15: =I9+I10+I11+I12+I13+I14 -> 848 | J15: =J9+J10+J11+J12+J13+J14 -> 848
A17: Num de positivos | B17: =COUNTIF(TRAIN!J:J,"positive") -> 571 | C17: =ROUND(B17/B19,3) -> 0.673
A18: Num de negativos | B18: =COUNTIF(TRAIN!J:J,"negative") -> 277 | C18: =ROUND(B18/B19,3) -> 0.327
A19: Total | B19: =B17+B18 -> 848
A25: middle-middle-square "x"
B27: top-left-square | C27: top-middle-square | D27: top-right-square | E27: middle-left-square | F27: middle-right-square | G27: bottom-left-square | H27: bottom-middle-square | I27: bottom-right-square
A28: Entropía general | B28: =ROUND((((B43/B45)*LOG(B43/B45,2))+((B44/B45)*LOG(B44/B45,2)))*-1,3) -> 0.711 | C28: =B28 -> 0.711 | D28: =C28 -> 0.711 | E28: =D28 -> 0.711 | F28: =E28 -> 0.711 | G28: =F28 -> 0.711 | H28: =G28 -> 0.711 | I28: =H28 -> 0.711
A29: Entropía X | B29: =ROUND((((B35/(B35+B36))*LOG(B35/(B35+B36),2))+((B36/(B35+B36))*LOG(B36/(B35+B36),2)))*-1,3) -> 0.519 | C29: =ROUND((((C35/(C35+C36))*LOG(C35/(C35+C36),2))+((C36/(C35+C36))*LOG(C36/(C35+C36),2)))*-1,3) -> 0.666 | D29: =ROUND((((D35/(D35+D36))*LOG(D35/(D35+D36),2))+((D36/(D35+D36))*LOG(D36/(D35+D36),2)))*-1,3) -> 0.625 | E29: =ROUND((((E35/(E35+E36))*LOG(E35/(E35+E36),2))+((E36/(E35+E36))*LOG(E36/(E35+E36),2)))*-1,3) -> 0.747 | F29: =ROUND((((F35/(F35+F36))*LOG(F35/(F35+F36),2))+((F36/(F35+F36))*LOG(F36/(F35+F36),2)))*-1,3) -> 0.75 | G29: =ROUND((((G35/(G35+G36))*LOG(G35/(G35+G36),2))+((G36/(G35+G36))*LOG(G36/(G35+G36),2)))*-1,3) -> 0.645 | H29: =ROUND((((H35/(H35+H36))*LOG(H35/(H35+H36),2))+((H36/(H35+H36))*LOG(H36/(H35+H36),2)))*-1,3) -> 0.78 | I29: =ROUND((((I35/(I35+I36))*LOG(I35/(I35+I36),2))+((I36/(I35+I36))*LOG(I36/(I35+I36),2)))*-1,3) -> 0.657
A30: Entropía B | B30: =ROUND((((B37/(B38+B37))*LOG(B37/(B38+B37),2))+((B38/(B37+B38))*LOG(B38/(B37+B38),2)))*-1,3) -> 0.637 | C30: =ROUND((((C37/(C38+C37))*LOG(C37/(C38+C37),2))+((C38/(C37+C38))*LOG(C38/(C37+C38),2)))*-1,3) -> 0.783 | D30: =ROUND((((D37/(D38+D37))*LOG(D37/(D38+D37),2))+((D38/(D37+D38))*LOG(D38/(D37+D38),2)))*-1,3) -> 0.568 | E30: =ROUND((((E37/(E38+E37))*LOG(E37/(E38+E37),2))+((E38/(E37+E38))*LOG(E38/(E37+E38),2)))*-1,3) -> 0.667 | F30: =ROUND((((F37/(F38+F37))*LOG(F37/(F38+F37),2))+((F38/(F37+F38))*LOG(F38/(F37+F38),2)))*-1,3) -> 0.725 | G30: =ROUND((((G37/(G38+G37))*LOG(G37/(G38+G37),2))+((G38/(G37+G38))*LOG(G38/(G37+G38),2)))*-1,3) -> 0.533 | H30: =ROUND((((H37/(H38+H37))*LOG(H37/(H38+H37),2))+((H38/(H37+H38))*LOG(H38/(H37+H38),2)))*-1,3) -> 0.718 | I30: =ROUND((((I37/(I38+I37))*LOG(I37/(I38+I37),2))+((I38/(I37+I38))*LOG(I38/(I37+I38),2)))*-1,3) -> 0.588
A31: Entropía O | B31: =ROUND((((B39/(B40+B39))*LOG(B39/(B40+B39),2))+((B40/(B39+B40))*LOG(B40/(B39+B40),2)))*-1,3) -> 0.868 | C31: =ROUND((((C39/(C40+C39))*LOG(C39/(C40+C39),2))+((C40/(C39+C40))*LOG(C40/(C39+C40),2)))*-1,3) -> 0.7 | D31: =ROUND((((D39/(D40+D39))*LOG(D39/(D40+D39),2))+((D40/(D39+D40))*LOG(D40/(D39+D40),2)))*-1,3) -> 0.842 | E31: =ROUND((((E39/(E40+E39))*LOG(E39/(E40+E39),2))+((E40/(E39+E40))*LOG(E40/(E39+E40),2)))*-1,3) -> 0.707 | F31: =ROUND((((F39/(F40+F39))*LOG(F39/(F40+F39),2))+((F40/(F39+F40))*LOG(F40/(F39+F40),2)))*-1,3) -> 0.664 | G31: =ROUND((((G39/(G40+G39))*LOG(G39/(G40+G39),2))+((G40/(G39+G40))*LOG(G40/(G39+G40),2)))*-1,3) -> 0.842 | H31: =ROUND((((H39/(H40+H39))*LOG(H39/(H40+H39),2))+((H40/(H39+H40))*LOG(H40/(H39+H40),2)))*-1,3) -> 0.63 | I31: =ROUND((((I39/(I40+I39))*LOG(I39/(I40+I39),2))+((I40/(I39+I40))*LOG(I40/(I39+I40),2)))*-1,3) -> 0.822
A32: Entropía final | B32: =ROUND(((((B35+B36)/B41)*B29)+(((B37+B38)/B41)*B30)+(((B39+B40)/B41)*B31)),3) -> 0.683 | C32: =ROUND(((((C35+C36)/C41)*C29)+(((C37+C38)/C41)*C30)+(((C39+C40)/C41)*C31)),3) -> 0.709 | D32: =ROUND(((((D35+D36)/D41)*D29)+(((D37+D38)/D41)*D30)+(((D39+D40)/D41)*D31)),3) -> 0.695 | E32: =ROUND(((((E35+E36)/E41)*E29)+(((E37+E38)/E41)*E30)+(((E39+E40)/E41)*E31)),3) -> 0.71 | F32: =ROUND(((((F35+F36)/F41)*F29)+(((F37+F38)/F41)*F30)+(((F39+F40)/F41)*F31)),3) -> 0.71 | G32: =ROUND(((((G35+G36)/G41)*G29)+(((G37+G38)/G41)*G30)+(((G39+G40)/G41)*G31)),3) -> 0.694 | H32: =ROUND(((((H35+H36)/H41)*H29)+(((H37+H38)/H41)*H30)+(((H39+H40)/H41)*H31)),3) -> 0.706 | I32: =ROUND(((((I35+I36)/I41)*I29)+(((I37+I38)/I41)*I30)+(((I39+I40)/I41)*I31)),3) -> 0.701
A33: Ganancia | B33: =ROUND((B28-B32),3) -> 0.028 | C33: =ROUND((C28-C32),3) -> 0.002 | D33: =ROUND((D28-D32),3) -> 0.016 | E33: =ROUND((E28-E32),3) -> 0.001 | F33: =ROUND((F28-F32),3) -> 0.001 | G33: =ROUND((G28-G32),3) -> 0.017 | H33: =ROUND((H28-H32),3) -> 0.005 | I33: =ROUND((I28-I32),3) -> 0.01
A35: X positivos | B35: =COUNTIFS(TRAIN!A:A,"x",TRAIN!J:J,"positive",TRAIN!E:E,"x") -> 144 | C35: =COUNTIFS(TRAIN!B:B,"x",TRAIN!J:J,"positive",TRAIN!E:E,"x") -> 119 | D35: =COUNTIFS(TRAIN!C:C,"x",TRAIN!J:J,"positive",TRAIN!E:E,"x") -> 135 | E35: =COUNTIFS(TRAIN!D:D,"x",TRAIN!J:J,"positive",TRAIN!E:E,"x") -> 111 | F35: =COUNTIFS(TRAIN!F:F,"x",TRAIN!J:J,"positive",TRAIN!E:E,"x") -> 110 | G35: =COUNTIFS(TRAIN!G:G,"x",TRAIN!J:J,"positive",TRAIN!E:E,"x") -> 132 | H35: =COUNTIFS(TRAIN!H:H,"x",TRAIN!J:J,"positive",TRAIN!E:E,"x") -> 113 | I35: =COUNTIFS(TRAIN!I:I,"x",TRAIN!J:J,"positive",TRAIN!E:E,"x") -> 137
A36: X negativos | B36: =COUNTIFS(TRAIN!A:A,"x",TRAIN!J:J,"negative",TRAIN!E:E,"x") -> 19 | C36: =COUNTIFS(TRAIN!B:B,"x",TRAIN!J:J,"negative",TRAIN!E:E,"x") -> 25 | D36: =COUNTIFS(TRAIN!C:C,"x",TRAIN!J:J,"negative",TRAIN!E:E,"x") -> 25 | E36: =COUNTIFS(TRAIN!D:D,"x",TRAIN!J:J,"negative",TRAIN!E:E,"x") -> 30 | F36: =COUNTIFS(TRAIN!F:F,"x",TRAIN!J:J,"negative",TRAIN!E:E,"x") -> 30 | G36: =COUNTIFS(TRAIN!G:G,"x",TRAIN!J:J,"negative",TRAIN!E:E,"x") -> 26 | H36: =COUNTIFS(TRAIN!H:H,"x",TRAIN!J:J,"negative",TRAIN!E:E,"x") -> 34 | I36: =COUNTIFS(TRAIN!I:I,"x",TRAIN!J:J,"negative",TRAIN!E:E,"x") -> 28
A37: B positivos | B37: =COUNTIFS(TRAIN!A:A,"b",TRAIN!J:J,"positive",TRAIN!E:E,"x") -> 73 | C37: =COUNTIFS(TRAIN!B:B,"b",TRAIN!J:J,"positive",TRAIN!E:E,"x") -> 79 | D37: =COUNTIFS(TRAIN!C:C,"b",TRAIN!J:J,"positive",TRAIN!E:E,"x") -> 84 | E37: =COUNTIFS(TRAIN!D:D,"b",TRAIN!J:J,"positive",TRAIN!E:E,"x") -> 90 | F37: =COUNTIFS(TRAIN!F:F,"b",TRAIN!J:J,"positive",TRAIN!E:E,"x") -> 91 | G37: =COUNTIFS(TRAIN!G:G,"b",TRAIN!J:J,"positive",TRAIN!E:E,"x") -> 87 | H37: =COUNTIFS(TRAIN!H:H,"b",TRAIN!J:J,"positive",TRAIN!E:E,"x") -> 89 | I37: =COUNTIFS(TRAIN!I:I,"b",TRAIN!J:J,"positive",TRAIN!E:E,"x") -> 85
A38: B negativos | B38: =COUNTIFS(TRAIN!A:A,"b",TRAIN!J:J,"negative",TRAIN!E:E,"x") -> 14 | C38: =COUNTIFS(TRAIN!B:B,"b",TRAIN!J:J,"negative",TRAIN!E:E,"x") -> 24 | D38: =COUNTIFS(TRAIN!C:C,"b",TRAIN!J:J,"negative",TRAIN!E:E,"x") -> 13 | E38: =COUNTIFS(TRAIN!D:D,"b",TRAIN!J:J,"negative",TRAIN!E:E,"x") -> 19 | F38: =COUNTIFS(TRAIN!F:F,"b",TRAIN!J:J,"negative",TRAIN!E:E,"x") -> 23 | G38: =COUNTIFS(TRAIN!G:G,"b",TRAIN!J:J,"negative",TRAIN!E:E,"x") -> 12 | H38: =COUNTIFS(TRAIN!H:H,"b",TRAIN!J:J,"negative",TRAIN!E:E,"x") -> 22 | I38: =COUNTIFS(TRAIN!I:I,"b",TRAIN!J:J,"negative",TRAIN!E:E,"x") -> 14
A39: O positivos | B39: =COUNTIFS(TRAIN!A:A,"o",TRAIN!J:J,"positive",TRAIN!E:E,"x") -> 118 | C39: =COUNTIFS(TRAIN!B:B,"o",TRAIN!J:J,"positive",TRAIN!E:E,"x") -> 137 | D39: =COUNTIFS(TRAIN!C:C,"o",TRAIN!J:J,"positive",TRAIN!E:E,"x") -> 116 | E39: =COUNTIFS(TRAIN!D:D,"o",TRAIN!J:J,"positive",TRAIN!E:E,"x") -> 134 | F39: =COUNTIFS(TRAIN!F:F,"o",TRAIN!J:J,"positive",TRAIN!E:E,"x") -> 134 | G39: =COUNTIFS(TRAIN!G:G,"o",TRAIN!J:J,"positive",TRAIN!E:E,"x") -> 116 | H39: =COUNTIFS(TRAIN!H:H,"o",TRAIN!J:J,"positive",TRAIN!E:E,"x") -> 133 | I39: =COUNTIFS(TRAIN!I:I,"o",TRAIN!J:J,"positive",TRAIN!E:E,"x") -> 113
A40: O negativos | B40: =COUNTIFS(TRAIN!A:A,"o",TRAIN!J:J,"negative",TRAIN!E:E,"x") -> 48 | C40: =COUNTIFS(TRAIN!B:B,"o",TRAIN!J:J,"negative",TRAIN!E:E,"x") -> 32 | D40: =COUNTIFS(TRAIN!C:C,"o",TRAIN!J:J,"negative",TRAIN!E:E,"x") -> 43 | E40: =COUNTIFS(TRAIN!D:D,"o",TRAIN!J:J,"negative",TRAIN!E:E,"x") -> 32 | F40: =COUNTIFS(TRAIN!F:F,"o",TRAIN!J:J,"negative",TRAIN!E:E,"x") -> 28 | G40: =COUNTIFS(TRAIN!G:G,"o",TRAIN!J:J,"negative",TRAIN!E:E,"x") -> 43 | H40: =COUNTIFS(TRAIN!H:H,"o",TRAIN!J:J,"negative",TRAIN!E:E,"x") -> 25 | I40: =COUNTIFS(TRAIN!I:I,"o",TRAIN!J:J,"negative",TRAIN!E:E,"x") -> 39
A41: Total | B41: =B35+B36+B37+B38+B39+B40 -> 416 | C41: =C35+C36+C37+C38+C39+C40 -> 416 | D41: =D35+D36+D37+D38+D39+D40 -> 416 | E41: =E35+E36+E37+E38+E39+E40 -> 416 | F41: =F35+F36+F37+F38+F39+F40 -> 416 | G41: =G35+G36+G37+G38+G39+G40 -> 416 | H41: =H35+H36+H37+H38+H39+H40 -> 416 | I41: =I35+I36+I37+I38+I39+I40 -> 416
A43: Num de positivos | B43: =COUNTIFS(TRAIN!E:E,"x",TRAIN!J:J,"positive") -> 335
A44: Num de negativos | B44: =COUNTIFS(TRAIN!E:E,"x",TRAIN!J:J,"negative") -> 81
A45: Total | B45: =B43+B44 -> 416
A52: middle-middle-square "b"
B54: top-middle-square | C54: top-right-square | D54: middle-left-square | E54: middle-right-square | F54: bottom-left-square | G54: bottom-middle-square | H54: bottom-right-square
A55: Entropía general | B55: =ROUND((((B70/B72)*LOG(B70/B72,2))+((B71/B72)*LOG(B71/B72,2)))*-1,3) -> 0.848 | C55: =B55 -> 0.848 | D55: =C55 -> 0.848 | E55: =D55 -> 0.848 | F55: =E55 -> 0.848 | G55: =F55 -> 0.848 | H55: =G55 -> 0.848
A56: Entropía X | B56: =ROUND((((B62/(B62+B63))*LOG(B62/(B62+B63),2))+((B63/(B62+B63))*LOG(B63/(B62+B63),2)))*-1,3) -> 0.899 | C56: =ROUND((((C62/(C62+C63))*LOG(C62/(C62+C63),2))+((C63/(C62+C63))*LOG(C63/(C62+C63),2)))*-1,3) -> 0.564 | D56: =ROUND((((D62/(D62+D63))*LOG(D62/(D62+D63),2))+((D63/(D62+D63))*LOG(D63/(D62+D63),2)))*-1,3) -> 0.939 | E56: =ROUND((((E62/(E62+E63))*LOG(E62/(E62+E63),2))+((E63/(E62+E63))*LOG(E63/(E62+E63),2)))*-1,3) -> 0.971 | F56: =ROUND((((F62/(F62+F63))*LOG(F62/(F62+F63),2))+((F63/(F62+F63))*LOG(F63/(F62+F63),2)))*-1,3) -> 0.681 | G56: =ROUND((((G62/(G62+G63))*LOG(G62/(G62+G63),2))+((G63/(G62+G63))*LOG(G63/(G62+G63),2)))*-1,3) -> 0.959 | H56: =ROUND((((H62/(H62+H63))*LOG(H62/(H62+H63),2))+((H63/(H62+H63))*LOG(H63/(H62+H63),2)))*-1,3) -> 0.678
A57: Entropía B | B57: =ROUND((((B64/(B65+B64))*LOG(B64/(B65+B64),2))+((B65/(B64+B65))*LOG(B65/(B64+B65),2)))*-1,3) -> 0.918 | C57: =ROUND((((C64/(C65+C64))*LOG(C64/(C65+C64),2))+((C65/(C64+C65))*LOG(C65/(C64+C65),2)))*-1,3) -> 0.877 | D57: =ROUND((((D64/(D65+D64))*LOG(D64/(D65+D64),2))+((D65/(D64+D65))*LOG(D65/(D64+D65),2)))*-1,3) -> 0.852 | E57: =ROUND((((E64/(E65+E64))*LOG(E64/(E65+E64),2))+((E65/(E64+E65))*LOG(E65/(E64+E65),2)))*-1,3) -> 0.776 | F57: =ROUND((((F64/(F65+F64))*LOG(F64/(F65+F64),2))+((F65/(F64+F65))*LOG(F65/(F64+F65),2)))*-1,3) -> 0.855 | G57: =ROUND((((G64/(G65+G64))*LOG(G64/(G65+G64),2))+((G65/(G64+G65))*LOG(G65/(G64+G65),2)))*-1,3) -> 0.746 | H57: =ROUND((((H64/(H65+H64))*LOG(H64/(H65+H64),2))+((H65/(H64+H65))*LOG(H65/(H64+H65),2)))*-1,3) -> 0.779
...

Sheet TRAIN
A1: top-left-square | B1: top-middle-square | C1: top-right-square | D1: middle-left-square | E1: middle-middle-square | F1: middle-right-square | G1: bottom-left-square | H1: bottom-middle-square | I1: bottom-right-square
A2: x | B2: x | C2: x | D2: x | E2: o | F2: o | G2: x | H2: o | I2: o | J2: positive
A3: x | B3: x | C3: x | D3: x | E3: o | F3: o | G3: o | H3: x | I3: o | J3: positive
A4: x | B4: x | C4: x | D4: x | E4: o | F4: o | G4: o | H4: o | I4: x | J4: positive
A5: x | B5: x | C5: x | D5: x | E5: o | F5: o | G5: o | H5: b | I5: b | J5: positive
A6: x | B6: x | C6: x | D6: x | E6: o | F6: o | G6: b | H6: o | I6: b | J6: positive
A7: x | B7: x | C7: x | D7: x | E7: o | F7: o | G7: b | H7: b | I7: o | J7: positive
A8: x | B8: x | C8: x | D8: x | E8: o | F8: b | G8: o | H8: o | I8: b | J8: positive
A9: x | B9: x | C9: x | D9: x | E9: o | F9: b | G9: o | H9: b | I9: o | J9: positive
A10: x | B10: x | C10: x | D10: x | E10: o | F10: b | G10: b | H10: o | I10: o | J10: positive
A11: x | B11: x | C11: x | D11: x | E11: b | F11: o | G11: o | H11: o | I11: b | J11: positive
A12: x | B12: x | C12: x | D12: x | E12: b | F12: o | G12: o | H12: b | I12: o | J12: positive
A13: x | B13: x | C13: x | D13: x | E13: b | F13: o | G13: b | H13: o | I13: o | J13: positive
... A849: o | B849: o | C849: x | D849: x | E849: x | F849: o | G849: o | H849: x | I849: x | J849: negative

Sheet TEST
A1: top-left-square | B1: top-middle-square | C1: top-right-square | D1: middle-left-square | E1: middle-middle-square | F1: middle-right-square | G1: bottom-left-square | H1: bottom-middle-square | I1: bottom-right-square
A2: b | B2: b | C2: x | D2: o | E2: x | F2: b | G2: x | H2: b | I2: o | J2: positive
A3: b | B3: b | C3: x | D3: o | E3: o | F3: x | G3: x | H3: o | I3: x | J3: positive
A4: b | B4: b | C4: x | D4: o | E4: o | F4: x | G4: o | H4: x | I4: x | J4: positive
A5: b | B5: b | C5: x | D5: o | E5: o | F5: x | G5: b | H5: b | I5: x | J5: positive
A6: b | B6: b | C6: x | D6: o | E6: b | F6: x | G6: o | H6: b | I6: x | J6: positive
A7: b | B7: b | C7: x | D7: o | E7: b | F7: x | G7: b | H7: o | I7: x | J7: positive
A8: b | B8: b | C8: x | D8: b | E8: x | F8: o | G8: x | H8: o | I8: b | J8: positive
A9: b | B9: b | C9: x | D9: b | E9: x | F9: o | G9: x | H9: b | I9: o | J9: positive
A10: b | B10: b | C10: x | D10: b | E10: x | F10: b | G10: x | H10: o | I10: o | J10: positive
A11: b | B11: b | C11: x | D11: b | E11: o | F11: x | G11: o | H11: b | I11: x | J11: positive
A12: b | B12: b | C12: x | D12: b | E12: o | F12: x | G12: b | H12: o | I12: x | J12: positive
A13: b | B13: b | C13: x | D13: b | E13: b | F13: x | G13: o | H13: o | I13: x | J13: positive
... A101: o | B101: b | C101: x | D101: o | E101: b | F101: x | G101: b | H101: b | I101: x | J101: positive

Sheet NEW
A1: top-left-square | B1: top-middle-square | C1: top-right-square | D1: middle-left-square | E1: middle-middle-square | F1: middle-right-square | G1: bottom-left-square | H1: bottom-middle-square | I1: bottom-right-square
A2: o | B2: o | C2: b | D2: x | E2: x | F2: x | G2: x | H2: b | I2: o
A3: o | B3: o | C3: b | D3: x | E3: x | F3: x | G3: o | H3: x | I3: b
A4: o | B4: o | C4: b | D4: x | E4: x | F4: x | G4: o | H4: b | I4: x
A5: o | B5: o | C5: b | D5: x | E5: x | F5: x | G5: b | H5: x | I5: o
A6: o | B6: o | C6: b | D6: x | E6: x | F6: x | G6: b | H6: o | I6: x
A7: x | B7: b | C7: b | D7: o | E7: o | F7: o | G7: b | H7: x | I7: x
A8: x | B8: b | C8: b | D8: b | E8: x | F8: x | G8: o | H8: o | I8: o
A9: o | B9: x | C9: x | D9: x | E9: x | F9: b | G9: o | H9: o | I9: o
A10: o | B10: x | C10: x | D10: x | E10: o | F10: x | G10: o | H10: b | I10: o
A11: o | B11: x | C11: x | D11: x | E11: o | F11: x | G11: b | H11: o | I11: o
